<?xml version="1.0"?>
<!-- =================================================================================== -->
<!-- |    This document was autogenerated by xacro from ../xacro/rvl/rvl_ur.xacro      | -->
<!-- |    EDITING THIS FILE BY HAND IS NOT RECOMMENDED                                 | -->
<!-- =================================================================================== -->
<robot name="rvl_ur">
  <!--
        Base UR robot series xacro macro.

        NOTE: this is NOT a URDF. It cannot directly be loaded by consumers
        expecting a flattened '.urdf' file. See the top-level '.xacro' for that
        (but note: that .xacro must still be processed by the xacro command).

        For use in '.launch' files: use one of the 'load_urX.launch' convenience
        launch files.

        This file models the base kinematic chain of a UR robot, which then gets
        parameterised by various configuration files to convert it into a UR3(e),
        UR5(e), UR10(e) or UR16e.

        NOTE: the default kinematic parameters (ie: link lengths, frame locations,
        offets, etc) do not correspond to any particular robot. They are defaults
        only. There WILL be non-zero offsets between the Forward Kinematics results
        in TF (ie: robot_state_publisher) and the values reported by the Teach
        Pendant.

        For accurate (and robot-specific) transforms, the 'kinematics_parameters_file'
        parameter MUST point to a .yaml file containing the appropriate values for
        the targetted robot.

        If using the UniversalRobots/Universal_Robots_ROS_Driver, follow the steps
        described in the readme of that repository to extract the kinematic
        calibration from the controller and generate the required .yaml file.

        Main author of the migration to yaml configs: Ludovic Delval.

        Contributors to previous versions (in no particular order):

        - Felix Messmer
        - Kelsey Hawkins
        - Wim Meeussen
        - Shaun Edwards
        - Nadia Hammoudeh Garcia
        - Dave Hershberger
        - G. vd. Hoorn
        - Philip Long
        - Dave Coleman
        - Miguel Prada
        - Mathias Luedtke
        - Marcel Schnirring
        - Felix von Drigalski
        - Felix Exner
        - Jimmy Da Silva
        - Ajit Krisshna N L
        - Muhammad Asif Rana
    -->
  <!--
    NOTE: the macro defined in this file is NOT part of the public API of this
          package. Users CANNOT rely on this file being available, or stored in
          this location. Nor can they rely on the existence of the macro.
  -->
  <transmission name="shoulder_pan_trans">
    <type>transmission_interface/SimpleTransmission</type>
    <joint name="shoulder_pan_joint">
      <hardwareInterface>hardware_interface/PositionJointInterface</hardwareInterface>
    </joint>
    <actuator name="shoulder_pan_motor">
      <mechanicalReduction>1</mechanicalReduction>
    </actuator>
  </transmission>
  <transmission name="shoulder_lift_trans">
    <type>transmission_interface/SimpleTransmission</type>
    <joint name="shoulder_lift_joint">
      <hardwareInterface>hardware_interface/PositionJointInterface</hardwareInterface>
    </joint>
    <actuator name="shoulder_lift_motor">
      <mechanicalReduction>1</mechanicalReduction>
    </actuator>
  </transmission>
  <transmission name="elbow_trans">
    <type>transmission_interface/SimpleTransmission</type>
    <joint name="elbow_joint">
      <hardwareInterface>hardware_interface/PositionJointInterface</hardwareInterface>
    </joint>
    <actuator name="elbow_motor">
      <mechanicalReduction>1</mechanicalReduction>
    </actuator>
  </transmission>
  <transmission name="wrist_1_trans">
    <type>transmission_interface/SimpleTransmission</type>
    <joint name="wrist_1_joint">
      <hardwareInterface>hardware_interface/PositionJointInterface</hardwareInterface>
    </joint>
    <actuator name="wrist_1_motor">
      <mechanicalReduction>1</mechanicalReduction>
    </actuator>
  </transmission>
  <transmission name="wrist_2_trans">
    <type>transmission_interface/SimpleTransmission</type>
    <joint name="wrist_2_joint">
      <hardwareInterface>hardware_interface/PositionJointInterface</hardwareInterface>
    </joint>
    <actuator name="wrist_2_motor">
      <mechanicalReduction>1</mechanicalReduction>
    </actuator>
  </transmission>
  <transmission name="wrist_3_trans">
    <type>transmission_interface/SimpleTransmission</type>
    <joint name="wrist_3_joint">
      <hardwareInterface>hardware_interface/PositionJointInterface</hardwareInterface>
    </joint>
    <actuator name="wrist_3_motor">
      <mechanicalReduction>1</mechanicalReduction>
    </actuator>
  </transmission>
  <!-- links: main serial chain -->
  <link name="base_link" />
  <link name="base_link_inertia">
    <visual>
      <origin rpy="0 0 3.141592653589793" xyz="0 0 0" />
      <geometry>
        <mesh filename="package://Models/universal_robots/ur5e/visual/base.dae" />
      </geometry>
    </visual>
    <collision>
      <origin rpy="0 0 3.141592653589793" xyz="0 0 0" />
      <geometry>
        <mesh filename="package://Models/universal_robots/ur5e/collision/base.stl" />
      </geometry>
    </collision>
    <inertial>
      <mass value="4.0" />
      <origin rpy="0 0 0" xyz="0 0 0" />
      <inertia ixx="0.00443333156" ixy="0.0" ixz="0.0" iyy="0.00443333156" iyz="0.0" izz="0.0072" />
    </inertial>
  </link>
  <link name="shoulder_link">
    <visual>
      <origin rpy="0 0 3.141592653589793" xyz="0 0 0" />
      <geometry>
        <mesh filename="package://Models/universal_robots/ur5e/visual/shoulder.dae" />
      </geometry>
    </visual>
    <collision>
      <origin rpy="0 0 3.141592653589793" xyz="0 0 0" />
      <geometry>
        <mesh filename="package://Models/universal_robots/ur5e/collision/shoulder.stl" />
      </geometry>
    </collision>
    <inertial>
      <mass value="3.7" />
      <origin rpy="0 0 0" xyz="0 0 0" />
      <inertia ixx="0.010267495893" ixy="0.0" ixz="0.0" iyy="0.010267495893" iyz="0.0" izz="0.00666" />
    </inertial>
  </link>
  <link name="upper_arm_link">
    <visual>
      <origin rpy="1.5707963267948966 0 -1.5707963267948966" xyz="0 0 0.138" />
      <geometry>
        <mesh filename="package://Models/universal_robots/ur5e/visual/upperarm.dae" />
      </geometry>
    </visual>
    <collision>
      <origin rpy="1.5707963267948966 0 -1.5707963267948966" xyz="0 0 0.138" />
      <geometry>
        <mesh filename="package://Models/universal_robots/ur5e/collision/upperarm.stl" />
      </geometry>
    </collision>
    <inertial>
      <mass value="8.393" />
      <origin rpy="0 1.5707963267948966 0" xyz="-0.2125 0.0 0.138" />
      <inertia ixx="0.1338857818623325" ixy="0.0" ixz="0.0" iyy="0.1338857818623325" iyz="0.0" izz="0.0151074" />
    </inertial>
  </link>
  <link name="forearm_link">
    <visual>
      <origin rpy="1.5707963267948966 0 -1.5707963267948966" xyz="0 0 0.007" />
      <geometry>
        <mesh filename="package://Models/universal_robots/ur5e/visual/forearm.dae" />
      </geometry>
    </visual>
    <collision>
      <origin rpy="1.5707963267948966 0 -1.5707963267948966" xyz="0 0 0.007" />
      <geometry>
        <mesh filename="package://Models/universal_robots/ur5e/collision/forearm.stl" />
      </geometry>
    </collision>
    <inertial>
      <mass value="2.275" />
      <origin rpy="0 1.5707963267948966 0" xyz="-0.1961 0.0 0.007" />
      <inertia ixx="0.031209355099586295" ixy="0.0" ixz="0.0" iyy="0.031209355099586295" iyz="0.0" izz="0.004095" />
    </inertial>
  </link>
  <link name="wrist_1_link">
    <visual>
      <!-- TODO: Move this to a parameter -->
      <origin rpy="1.5707963267948966 0 0" xyz="0 0 -0.127" />
      <geometry>
        <mesh filename="package://Models/universal_robots/ur5e/visual/wrist1.dae" />
      </geometry>
    </visual>
    <collision>
      <origin rpy="1.5707963267948966 0 0" xyz="0 0 -0.127" />
      <geometry>
        <mesh filename="package://Models/universal_robots/ur5e/collision/wrist1.stl" />
      </geometry>
    </collision>
    <inertial>
      <mass value="1.219" />
      <origin rpy="0 0 0" xyz="0 0 0" />
      <inertia ixx="0.0025598989760400002" ixy="0.0" ixz="0.0" iyy="0.0025598989760400002" iyz="0.0" izz="0.0021942" />
    </inertial>
  </link>
  <link name="wrist_2_link">
    <visual>
      <origin rpy="0 0 0" xyz="0 0 -0.0997" />
      <geometry>
        <mesh filename="package://Models/universal_robots/ur5e/visual/wrist2.dae" />
      </geometry>
    </visual>
    <collision>
      <origin rpy="0 0 0" xyz="0 0 -0.0997" />
      <geometry>
        <mesh filename="package://Models/universal_robots/ur5e/collision/wrist2.stl" />
      </geometry>
    </collision>
    <inertial>
      <mass value="1.219" />
      <origin rpy="0 0 0" xyz="0 0 0" />
      <inertia ixx="0.0025598989760400002" ixy="0.0" ixz="0.0" iyy="0.0025598989760400002" iyz="0.0" izz="0.0021942" />
    </inertial>
  </link>
  <link name="wrist_3_link">
    <visual>
      <origin rpy="1.5707963267948966 0 0" xyz="0 0 -0.0989" />
      <geometry>
        <mesh filename="package://Models/universal_robots/ur5e/visual/wrist3.dae" />
      </geometry>
    </visual>
    <collision>
      <origin rpy="1.5707963267948966 0 0" xyz="0 0 -0.0989" />
      <geometry>
        <mesh filename="package://Models/universal_robots/ur5e/collision/wrist3.stl" />
      </geometry>
    </collision>
    <inertial>
      <mass value="0.1879" />
      <origin rpy="0 0 0" xyz="0.0 0.0 -0.0229" />
      <inertia ixx="9.890410052167731e-05" ixy="0.0" ixz="0.0" iyy="9.890410052167731e-05" iyz="0.0" izz="0.0001321171875" />
    </inertial>
  </link>
  <!-- joints: main serial chain -->
  <joint name="base_link-base_link_inertia" type="fixed">
    <parent link="base_link" />
    <child link="base_link_inertia" />
    <!--
                'base_link' is REP-103 aligned (so X+ forward), while the internal
                frames of the robot/controller have X+ pointing backwards.
                Use the joint between 'base_link' and 'base_link_inertia' (a dummy
                link/frame) to introduce the necessary rotation over Z (of pi rad).
            -->
    <origin rpy="0 0 3.141592653589793" xyz="0 0 0" />
  </joint>
  <joint name="shoulder_pan_joint" type="revolute">
    <parent link="base_link_inertia" />
    <child link="shoulder_link" />
    <origin rpy="0 0 -5.991681506500868e-08" xyz="0 0 0.1627616112650263" />
    <axis xyz="0 0 1" />
    <limit effort="150.0" lower="-6.283185307179586" upper="6.283185307179586" velocity="3.141592653589793" />
    <dynamics damping="0" friction="0" />
  </joint>
  <joint name="shoulder_lift_joint" type="revolute">
    <parent link="shoulder_link" />
    <child link="upper_arm_link" />
    <origin rpy="1.568695822980486 0 2.350143582628094e-06" xyz="0.0001171864022656332 0 0" />
    <axis xyz="0 0 1" />
    <limit effort="150.0" lower="-6.283185307179586" upper="6.283185307179586" velocity="3.141592653589793" />
    <dynamics damping="0" friction="0" />
  </joint>
  <joint name="elbow_joint" type="revolute">
    <parent link="upper_arm_link" />
    <child link="forearm_link" />
    <origin rpy="3.141279979860951 3.138418572813499 3.141588694100498" xyz="-0.4255477404386134 0 0" />
    <axis xyz="0 0 1" />
    <limit effort="150.0" lower="-3.141592653589793" upper="3.141592653589793" velocity="3.141592653589793" />
    <dynamics damping="0" friction="0" />
  </joint>
  <joint name="wrist_1_joint" type="revolute">
    <parent link="forearm_link" />
    <child link="wrist_1_link" />
    <origin rpy="0.003362351718143002 -0.001385386431977988 1.052643010408702e-05" xyz="-0.3926470322593426 -0.0004490249165745644 0.1335443945419522" />
    <axis xyz="0 0 1" />
    <limit effort="28.0" lower="-6.283185307179586" upper="6.283185307179586" velocity="3.141592653589793" />
    <dynamics damping="0" friction="0" />
  </joint>
  <joint name="wrist_2_joint" type="revolute">
    <parent link="wrist_1_link" />
    <child link="wrist_2_link" />
    <origin rpy="1.569952260231459 0 4.512455664684723e-08" xyz="2.411651959975612e-06 -0.09979265928964354 8.42316669864543e-05" />
    <axis xyz="0 0 1" />
    <limit effort="28.0" lower="-6.283185307179586" upper="6.283185307179586" velocity="3.141592653589793" />
    <dynamics damping="0" friction="0" />
  </joint>
  <joint name="wrist_3_joint" type="revolute">
    <parent link="wrist_2_link" />
    <child link="wrist_3_link" />
    <origin rpy="1.572166526344426 3.141592653589793 -3.14159262258105" xyz="-1.62560369067358e-06 0.09963772799936342 0.0001365236554595149" />
    <axis xyz="0 0 1" />
    <limit effort="28.0" lower="-6.283185307179586" upper="6.283185307179586" velocity="3.141592653589793" />
    <dynamics damping="0" friction="0" />
  </joint>
  <!-- ROS-Industrial 'base' frame: base_link to UR 'Base' Coordinates transform -->
  <link name="base" />
  <joint name="base_link-base_fixed_joint" type="fixed">
    <!--
                Note the rotation over Z of pi radians: as base_link is REP-103
                aligned (ie: has X+ forward, Y+ left and Z+ up), this is needed
                to correctly align 'base' with the 'Base' coordinate system of
                the UR controller.
            -->
    <origin rpy="0 0 3.141592653589793" xyz="0 0 0" />
    <parent link="base_link" />
    <child link="base" />
  </joint>
  <!-- ROS-Industrial 'flange' frame: attachment point for EEF models -->
  <link name="flange" />
  <joint name="wrist_3-flange" type="fixed">
    <parent link="wrist_3_link" />
    <child link="flange" />
    <origin rpy="0 -1.5707963267948966 -1.5707963267948966" xyz="0 0 0" />
  </joint>
  <!-- ROS-Industrial 'tool0' frame: all-zeros tool frame -->
  <link name="tool0" />
  <joint name="flange-tool0" type="fixed">
    <!-- default toolframe: X+ left, Y+ up, Z+ front -->
    <origin rpy="1.5707963267948966 0 1.5707963267948966" xyz="0 0 0" />
    <parent link="flange" />
    <child link="tool0" />
  </joint>
  <!-- LINK NAMES -->
  <!-- INDIVIDUAL LINK CONFIGS -->
  <!-- INDIVIDUAL JOINT NAMES -->
  <!-- INDIVIDUAL JOINT CONFIGS -->
  <transmission name="finger_joint_trans">
    <type>transmission_interface/SimpleTransmission</type>
    <joint name="knuckle_joint">
      <hardwareInterface>hardware_interface/EffortJointInterface</hardwareInterface>
    </joint>
    <actuator name="knuckle_joint_motor">
      <mechanicalReduction>1</mechanicalReduction>
    </actuator>
  </transmission>
  <!-- LINK MACROS -->
  <!-- JOINT MACROS -->
  <!-- ACTUALLY DEFINING THE ROBOT -->
  <!-- BASE PALM -->
  <link name="robotiq_2f_base_palm">
    <visual>
      <origin rpy="0 0 0" xyz="0 0 0" />
      <geometry>
        <mesh filename="package://Models/robotiq/2f_85/visual/robotiq_arg2f_base_link.stl" scale="1 1 1" />
      </geometry>
      <material name="robotiq_black">
        <color rgba="0.1 0.1 0.1 1" />
      </material>
    </visual>
    <collision>
      <origin rpy="0 0 0" xyz="0 0 0" />
      <geometry>
        <mesh filename="package://Models/robotiq/2f_85/collision/robotiq_arg2f_base_link.stl" scale="1 1 1" />
      </geometry>
    </collision>
    <inertial>
      <origin rpy="0 0 0" xyz="8.625E-08 -4.6583E-06 0.03145" />
      <mass value="0.22652" />
      <inertia ixx="0.00020005" ixy="-4.2442e-10" ixz="-2.9069e-10" iyy="0.00017832" iyz="-3.4402e-08" izz="0.00013478" />
    </inertial>
  </link>
  <link name="left_knuckle_link">
    <visual>
      <origin rpy="0 0 0" xyz="0 0 0" />
      <geometry>
        <mesh filename="package://Models/robotiq/2f_85/visual/robotiq_arg2f_85_outer_knuckle.dae" scale="0.001 0.001 0.001" />
      </geometry>
      <material name="robotiq_grey">
        <color rgba="0.792156862745098 0.819607843137255 0.933333333333333 1" />
      </material>
    </visual>
    <collision>
      <origin rpy="0 0 0" xyz="0 0 0" />
      <geometry>
        <mesh filename="package://Models/robotiq/2f_85/collision/robotiq_arg2f_85_outer_knuckle.dae" scale="0.001 0.001 0.001" />
      </geometry>
    </collision>
    <inertial>
      <origin rpy="0 0 0" xyz="-0.000200000000003065 0.0199435877845359 0.0292245259211331" />
      <mass value="0.00853198276973456" />
      <inertia ixx="2.89328108496468e-06" ixy="-1.57935047237397e-19" ixz="-1.93980378593255e-19" iyy="1.86719750325683e-06" iyz="-1.21858577871576e-06" izz="1.21905238907251e-06" />
    </inertial>
  </link>
  <link name="left_bar_link">
    <visual>
      <origin rpy="0 0 0" xyz="0 0 0" />
      <geometry>
        <mesh filename="package://Models/robotiq/2f_85/visual/robotiq_arg2f_85_outer_finger.dae" scale="0.001 0.001 0.001" />
      </geometry>
      <material name="robotiq_black">
        <color rgba="0.1 0.1 0.1 1" />
      </material>
    </visual>
    <collision>
      <origin rpy="0 0 0" xyz="0 0 0" />
      <geometry>
        <mesh filename="package://Models/robotiq/2f_85/collision/robotiq_arg2f_85_outer_finger.dae" scale="0.001 0.001 0.001" />
      </geometry>
    </collision>
    <inertial>
      <origin rpy="0 0 0" xyz="0.00030115855001899 0.0373907951953854 -0.0208027427000385" />
      <mass value="0.022614240507152" />
      <inertia ixx="1.52518312458174e-05" ixy="9.76583423954399e-10" ixz="-5.43838577022588e-10" iyy="6.17694243867776e-06" iyz="6.78636130740228e-06" izz="1.16494917907219e-05" />
    </inertial>
  </link>
  <link name="left_proximal_phalanx_link">
    <visual>
      <origin rpy="0 0 0" xyz="0 0 0" />
      <geometry>
        <mesh filename="package://Models/robotiq/2f_85/visual/robotiq_arg2f_85_inner_knuckle.dae" scale="0.001 0.001 0.001" />
      </geometry>
      <material name="robotiq_black">
        <color rgba="0.1 0.1 0.1 1" />
      </material>
    </visual>
    <collision>
      <origin rpy="0 0 0" xyz="0 0 0" />
      <geometry>
        <mesh filename="package://Models/robotiq/2f_85/collision/robotiq_arg2f_85_inner_knuckle.dae" scale="0.001 0.001 0.001" />
      </geometry>
    </collision>
    <inertial>
      <origin rpy="0 0 0" xyz="0.000123011831763771 0.0507850843201817 0.00103968640075166" />
      <mass value="0.0271177346495152" />
      <inertia ixx="2.61910379223783e-05" ixy="-2.43616858946494e-07" ixz="-6.37789906117123e-09" iyy="2.8270243746167e-06" iyz="-5.37200748039765e-07" izz="2.83695868220296e-05" />
    </inertial>
  </link>
  <link name="left_distal_phalanx_link">
    <visual>
      <origin rpy="0 0 0" xyz="0 0 0" />
      <geometry>
        <mesh filename="package://Models/robotiq/2f_85/visual/robotiq_arg2f_85_inner_finger.dae" scale="0.001 0.001 0.001" />
      </geometry>
      <material name="robotiq_black">
        <color rgba="0.1 0.1 0.1 1" />
      </material>
    </visual>
    <collision>
      <origin rpy="0 0 0" xyz="0 0 0" />
      <geometry>
        <mesh filename="package://Models/robotiq/2f_85/collision/robotiq_arg2f_85_inner_finger.dae" scale="0.001 0.001 0.001" />
      </geometry>
    </collision>
    <inertial>
      <origin rpy="0 0 0" xyz="0.000299999999999317 0.0160078233491243 -0.0136945669206257" />
      <mass value="0.0271177346495152" />
      <inertia ixx="2.71909453810972e-06" ixy="1.35402465472579e-21" ixz="-7.1817349065269e-22" iyy="7.69100314106116e-07" iyz="6.74715432769696e-07" izz="2.30315190420171e-06" />
    </inertial>
  </link>
  <link name="left_finger_tip_link">
    <visual>
      <origin rpy="0 0 0" xyz="0 0 0" />
      <geometry>
        <box size="0.022 0.00635 0.0375" />
      </geometry>
      <material name="robotiq_white">
        <color rgba="0.9 0.9 0.9 1" />
      </material>
    </visual>
    <collision>
      <origin rpy="0 0 0" xyz="0 0 0" />
      <geometry>
        <box size="0.022 0.00635 0.0375" />
      </geometry>
    </collision>
  </link>
  <joint name="left_bar_joint" type="fixed">
    <origin rpy="0 0 0" xyz="0 0.0315 -0.0041" />
    <parent link="left_knuckle_link" />
    <child link="left_bar_link" />
    <axis xyz="1 0 0" />
  </joint>
  <joint name="left_distal_joint" type="revolute">
    <origin rpy="0 0 0" xyz="0 0.0061 0.0471" />
    <parent link="left_bar_link" />
    <child link="left_distal_phalanx_link" />
    <axis xyz="1 0 0" />
    <limit effort="1000" lower="-0.8757" upper="0" velocity="0.5" />
    <mimic joint="knuckle_joint" multiplier="-1" offset="0" />
  </joint>
  <joint name="left_proximal_joint" type="revolute">
    <origin rpy="0 0 3.141592653589793" xyz="0 -0.0127 0.06142" />
    <parent link="robotiq_2f_base_palm" />
    <child link="left_proximal_phalanx_link" />
    <axis xyz="1 0 0" />
    <limit effort="1000" lower="0" upper="0.8757" velocity="0.5" />
    <mimic joint="knuckle_joint" multiplier="1" offset="0" />
  </joint>
  <joint name="left_tip_joint" type="fixed">
    <origin rpy="0 0 0" xyz="0 -0.0220203446692936 0.03242" />
    <parent link="left_distal_phalanx_link" />
    <child link="left_finger_tip_link" />
    <axis xyz="0 0 1" />
  </joint>
  <joint name="knuckle_joint" type="revolute">
    <origin rpy="0 0 3.141592654" xyz="0 -0.0306011 0.054904" />
    <parent link="robotiq_2f_base_palm" />
    <child link="left_knuckle_link" />
    <axis xyz="1 0 0" />
    <limit effort="1000" lower="0.0" upper="0.8" velocity="0.5" />
  </joint>
  <link name="right_knuckle_link">
    <visual>
      <origin rpy="0 0 0" xyz="0 0 0" />
      <geometry>
        <mesh filename="package://Models/robotiq/2f_85/visual/robotiq_arg2f_85_outer_knuckle.dae" scale="0.001 0.001 0.001" />
      </geometry>
      <material name="robotiq_grey">
        <color rgba="0.792156862745098 0.819607843137255 0.933333333333333 1" />
      </material>
    </visual>
    <collision>
      <origin rpy="0 0 0" xyz="0 0 0" />
      <geometry>
        <mesh filename="package://Models/robotiq/2f_85/collision/robotiq_arg2f_85_outer_knuckle.dae" scale="0.001 0.001 0.001" />
      </geometry>
    </collision>
    <inertial>
      <origin rpy="0 0 0" xyz="-0.000200000000003065 0.0199435877845359 0.0292245259211331" />
      <mass value="0.00853198276973456" />
      <inertia ixx="2.89328108496468e-06" ixy="-1.57935047237397e-19" ixz="-1.93980378593255e-19" iyy="1.86719750325683e-06" iyz="-1.21858577871576e-06" izz="1.21905238907251e-06" />
    </inertial>
  </link>
  <link name="right_bar_link">
    <visual>
      <origin rpy="0 0 0" xyz="0 0 0" />
      <geometry>
        <mesh filename="package://Models/robotiq/2f_85/visual/robotiq_arg2f_85_outer_finger.dae" scale="0.001 0.001 0.001" />
      </geometry>
      <material name="robotiq_black">
        <color rgba="0.1 0.1 0.1 1" />
      </material>
    </visual>
    <collision>
      <origin rpy="0 0 0" xyz="0 0 0" />
      <geometry>
        <mesh filename="package://Models/robotiq/2f_85/collision/robotiq_arg2f_85_outer_finger.dae" scale="0.001 0.001 0.001" />
      </geometry>
    </collision>
    <inertial>
      <origin rpy="0 0 0" xyz="0.00030115855001899 0.0373907951953854 -0.0208027427000385" />
      <mass value="0.022614240507152" />
      <inertia ixx="1.52518312458174e-05" ixy="9.76583423954399e-10" ixz="-5.43838577022588e-10" iyy="6.17694243867776e-06" iyz="6.78636130740228e-06" izz="1.16494917907219e-05" />
    </inertial>
  </link>
  <link name="right_proximal_phalanx_link">
    <visual>
      <origin rpy="0 0 0" xyz="0 0 0" />
      <geometry>
        <mesh filename="package://Models/robotiq/2f_85/visual/robotiq_arg2f_85_inner_knuckle.dae" scale="0.001 0.001 0.001" />
      </geometry>
      <material name="robotiq_black">
        <color rgba="0.1 0.1 0.1 1" />
      </material>
    </visual>
    <collision>
      <origin rpy="0 0 0" xyz="0 0 0" />
      <geometry>
        <mesh filename="package://Models/robotiq/2f_85/collision/robotiq_arg2f_85_inner_knuckle.dae" scale="0.001 0.001 0.001" />
      </geometry>
    </collision>
    <inertial>
      <origin rpy="0 0 0" xyz="0.000123011831763771 0.0507850843201817 0.00103968640075166" />
      <mass value="0.0271177346495152" />
      <inertia ixx="2.61910379223783e-05" ixy="-2.43616858946494e-07" ixz="-6.37789906117123e-09" iyy="2.8270243746167e-06" iyz="-5.37200748039765e-07" izz="2.83695868220296e-05" />
    </inertial>
  </link>
  <link name="right_distal_phalanx_link">
    <visual>
      <origin rpy="0 0 0" xyz="0 0 0" />
      <geometry>
        <mesh filename="package://Models/robotiq/2f_85/visual/robotiq_arg2f_85_inner_finger.dae" scale="0.001 0.001 0.001" />
      </geometry>
      <material name="robotiq_black">
        <color rgba="0.1 0.1 0.1 1" />
      </material>
    </visual>
    <collision>
      <origin rpy="0 0 0" xyz="0 0 0" />
      <geometry>
        <mesh filename="package://Models/robotiq/2f_85/collision/robotiq_arg2f_85_inner_finger.dae" scale="0.001 0.001 0.001" />
      </geometry>
    </collision>
    <inertial>
      <origin rpy="0 0 0" xyz="0.000299999999999317 0.0160078233491243 -0.0136945669206257" />
      <mass value="0.0271177346495152" />
      <inertia ixx="2.71909453810972e-06" ixy="1.35402465472579e-21" ixz="-7.1817349065269e-22" iyy="7.69100314106116e-07" iyz="6.74715432769696e-07" izz="2.30315190420171e-06" />
    </inertial>
  </link>
  <link name="right_finger_tip_link">
    <visual>
      <origin rpy="0 0 0" xyz="0 0 0" />
      <geometry>
        <box size="0.022 0.00635 0.0375" />
      </geometry>
      <material name="robotiq_white">
        <color rgba="0.9 0.9 0.9 1" />
      </material>
    </visual>
    <collision>
      <origin rpy="0 0 0" xyz="0 0 0" />
      <geometry>
        <box size="0.022 0.00635 0.0375" />
      </geometry>
    </collision>
  </link>
  <joint name="right_bar_joint" type="fixed">
    <origin rpy="0 0 0" xyz="0 0.0315 -0.0041" />
    <parent link="right_knuckle_link" />
    <child link="right_bar_link" />
    <axis xyz="1 0 0" />
  </joint>
  <joint name="right_distal_joint" type="revolute">
    <origin rpy="0 0 0" xyz="0 0.0061 0.0471" />
    <parent link="right_bar_link" />
    <child link="right_distal_phalanx_link" />
    <axis xyz="1 0 0" />
    <limit effort="1000" lower="-0.8757" upper="0" velocity="0.5" />
    <mimic joint="knuckle_joint" multiplier="-1" offset="0" />
  </joint>
  <joint name="right_proximal_joint" type="revolute">
    <origin rpy="0 0 0.0" xyz="0 0.0127 0.06142" />
    <parent link="robotiq_2f_base_palm" />
    <child link="right_proximal_phalanx_link" />
    <axis xyz="1 0 0" />
    <limit effort="1000" lower="0" upper="0.8757" velocity="0.5" />
    <mimic joint="knuckle_joint" multiplier="1" offset="0" />
  </joint>
  <joint name="right_tip_joint" type="fixed">
    <origin rpy="0 0 0" xyz="0 -0.0220203446692936 0.03242" />
    <parent link="right_distal_phalanx_link" />
    <child link="right_finger_tip_link" />
    <axis xyz="0 0 1" />
  </joint>
  <joint name="right_knuckle_joint" type="revolute">
    <origin rpy="0 0 0" xyz="0 0.0306011 0.054904" />
    <parent link="robotiq_2f_base_palm" />
    <child link="right_knuckle_link" />
    <axis xyz="1 0 0" />
    <limit effort="1000" lower="0.0" upper="0.8" velocity="0.5" />
    <mimic joint="knuckle_joint" multiplier="1" offset="0" />
  </joint>
  <joint name="tool0-robotiq_2f_base_palm" type="fixed">
    <parent link="tool0" />
    <child link="robotiq_2f_base_palm" />
    <origin rpy="0.0 0.0 1.5707963267948966" xyz="0.0 0.0 0.0053" />
  </joint>
  <material name="black">
    <color rgba="0.0 0.0 0.0 1.0" />
  </material>
  <material name="blue">
    <color rgba="0.0 0.0 0.8 1.0" />
  </material>
  <material name="green">
    <color rgba="0.0 0.8 0.0 1.0" />
  </material>
  <material name="grey">
    <color rgba="0.2 0.2 0.2 1.0" />
  </material>
  <material name="orange">
    <color rgba="1.0 0.4235294117647059 0.0392156862745098 1.0" />
  </material>
  <material name="brown">
    <color rgba="0.8705882352941177 0.8117647058823529 0.7647058823529411 1.0" />
  </material>
  <material name="red">
    <color rgba="0.8 0.0 0.0 1.0" />
  </material>
  <material name="white">
    <color rgba="1.0 1.0 1.0 1.0" />
  </material>
  <material name="aluminum">
    <color rgba="0.5 0.5 0.5 1" />
  </material>
  <material name="plastic">
    <color rgba="0.1 0.1 0.1 1" />
  </material>
  <!-- this specific plug does not apply to L515 -->
  <!-- camera body, with origin at bottom screw mount -->
  <joint name="L515_joint" type="fixed">
    <origin rpy="1.5707963267948966 -1.5707963267948966 0.0" xyz="0.0 -0.087 0.0203" />
    <parent link="tool0" />
    <child link="L515_bottom_screw_frame" />
  </joint>
  <link name="L515_bottom_screw_frame" />
  <joint name="L515_link_joint" type="fixed">
    <origin rpy="0 0 0" xyz="0.007500000000000001 0.0 0.021150000000000002" />
    <parent link="L515_bottom_screw_frame" />
    <child link="L515_link" />
  </joint>
  <!-- MAIN CAMERA LINK -->
  <link name="L515_link">
    <visual>
      <origin rpy="1.5707963267948966 0 1.5707963267948966" xyz="0.0045 0 0.009000000000000001" />
      <geometry>
        <mesh filename="package://Models/realsense/l515.dae" />
      </geometry>
    </visual>
    <collision>
      <origin rpy="1.5707963267948966 0 1.5707963267948966" xyz="-0.0085 0 0.009000000000000001" />
      <geometry>
        <cylinder length="0.026" radius="0.0305" />
      </geometry>
    </collision>
    <inertial>
      <!-- The following are not reliable values, and should not be used for modeling -->
      <!-- calculated assuming full cylinder as described here: https://en.wikipedia.org/wiki/List_of_moments_of_inertia -->
      <mass value="0.095" />
      <origin xyz="0 0 0" />
      <inertia ixx="0.000044" ixy="0.0" ixz="0.0" iyy="0.000027" iyz="0.0" izz="0.000027" />
    </inertial>
  </link>
  <joint name="L515_lower_mount_joint" type="fixed">
    <origin rpy="0 0 0" xyz="-0.013999999999999999 0 0.01015" />
    <parent link="L515_bottom_screw_frame" />
    <child link="L515_lower_mount" />
  </joint>
  <link name="L515_lower_mount" />
  <joint name="L515_upper_mount_joint" type="fixed">
    <origin rpy="0 0 0" xyz="-0.013999999999999999 0 0.05015" />
    <parent link="L515_bottom_screw_frame" />
    <child link="L515_upper_mount" />
  </joint>
  <link name="L515_upper_mount" />
  <!-- USB PLUG -->
  <joint name="L515_usb_plug_joint" type="fixed">
    <origin rpy="0.7853981633974483 0 0 " xyz="-0.0028000000000000004 -0.018 0.018" />
    <parent link="L515_bottom_screw_frame" />
    <child link="L515_usb_plug_link" />
  </joint>
  <link name="L515_usb_plug_link">
    <visual>
      <!-- 0.044850 0.008000 0.018500 -->
      <origin rpy="0 0 1.5707963267948966" xyz="0. -0.022425 0." />
      <geometry>
        <!--box size="0.044850 0.008 0.0185" /-->
        <mesh filename="package://Models/realsense/plug.stl" />
      </geometry>
      <material name="plastic" />
    </visual>
    <collision>
      <origin rpy="0 0 1.5707963267948966" xyz="0. -0.022425 0." />
      <geometry>
        <!--box size="0.044850 0.008 0.0185" /-->
        <mesh filename="package://Models/realsense/plug_collision.stl" />
      </geometry>
    </collision>
  </link>
  <!-- testing -->
  <!-- <xacro:L515_mounting_plate prefix="" /> -->
  <link name="L515_mounting_plate">
    <!-- <inertial>
                <origin xyz="0.0 0.0 0.0" rpy="0.0 0.0 0.0"/>
                <mass value="0.0"/>
                <inertia ixx="0.0" ixy="0.0" ixz="0.0" iyy="0.0" iyz="0.0" izz="0.0"/>
            </inertial> -->
    <visual name="">
      <origin rpy="0.0 0.0 0.0" xyz="0.0 0.0 0.0" />
      <geometry>
        <mesh filename="package://Models/mounting_plate.stl" />
      </geometry>
      <material name="opague_plastic">
        <color rgba="1.0 1.0 1.0 1.0" />
      </material>
    </visual>
    <collision>
      <origin rpy="0.0 0.0 0.0" xyz="0.0 0.0 0.0" />
      <geometry>
        <mesh filename="package://Models/mounting_plate.stl" />
      </geometry>
    </collision>
  </link>
  <joint name="tool0-mounting_plate" type="fixed">
    <parent link="tool0" />
    <child link="L515_mounting_plate" />
    <origin rpy="0.0 0.0 3.141592653589793" xyz="0.0 0.0 0.0" />
  </joint>
  <!-- Additional link for planning (center of gripper tips when fully closed) -->
  <link name="gripper_center_tip" />
  <joint name="gripper_center_tip_joint" type="fixed">
    <parent link="tool0" />
    <child link="gripper_center_tip" />
    <origin rpy="0.0 0.0 0.0" xyz="0.0 0.0 0.15182" />
  </joint>
  <!--DISABLE COLLISIONS: By default it is assumed that any link of the robot could potentially come into collision with any other link in the robot. This tag disables collision checking between a specified pair of links. -->
  <disable_collision link1="L515_link" link2="L515_mounting_plate"></disable_collision>
  <disable_collision link1="L515_link" link2="L515_usb_plug_link"></disable_collision>
  <disable_collision link1="L515_link" link2="left_bar_link"></disable_collision>
  <disable_collision link1="L515_link" link2="left_distal_phalanx_link"></disable_collision>
  <disable_collision link1="L515_link" link2="left_finger_tip_link"></disable_collision>
  <disable_collision link1="L515_link" link2="left_knuckle_link"></disable_collision>
  <disable_collision link1="L515_link" link2="left_proximal_phalanx_link"></disable_collision>
  <disable_collision link1="L515_link" link2="right_bar_link"></disable_collision>
  <disable_collision link1="L515_link" link2="right_distal_phalanx_link"></disable_collision>
  <disable_collision link1="L515_link" link2="right_finger_tip_link"></disable_collision>
  <disable_collision link1="L515_link" link2="right_knuckle_link"></disable_collision>
  <disable_collision link1="L515_link" link2="right_proximal_phalanx_link"></disable_collision>
  <disable_collision link1="L515_link" link2="robotiq_2f_base_palm"></disable_collision>
  <disable_collision link1="L515_link" link2="wrist_1_link"></disable_collision>
  <disable_collision link1="L515_link" link2="wrist_2_link"></disable_collision>
  <disable_collision link1="L515_link" link2="wrist_3_link"></disable_collision>
  <disable_collision link1="L515_mounting_plate" link2="L515_usb_plug_link"></disable_collision>
  <disable_collision link1="L515_mounting_plate" link2="left_bar_link"></disable_collision>
  <disable_collision link1="L515_mounting_plate" link2="left_distal_phalanx_link"></disable_collision>
  <disable_collision link1="L515_mounting_plate" link2="left_finger_tip_link"></disable_collision>
  <disable_collision link1="L515_mounting_plate" link2="left_knuckle_link"></disable_collision>
  <disable_collision link1="L515_mounting_plate" link2="left_proximal_phalanx_link"></disable_collision>
  <disable_collision link1="L515_mounting_plate" link2="right_bar_link"></disable_collision>
  <disable_collision link1="L515_mounting_plate" link2="right_distal_phalanx_link"></disable_collision>
  <disable_collision link1="L515_mounting_plate" link2="right_finger_tip_link"></disable_collision>
  <disable_collision link1="L515_mounting_plate" link2="right_knuckle_link"></disable_collision>
  <disable_collision link1="L515_mounting_plate" link2="right_proximal_phalanx_link"></disable_collision>
  <disable_collision link1="L515_mounting_plate" link2="robotiq_2f_base_palm"></disable_collision>
  <disable_collision link1="L515_mounting_plate" link2="wrist_1_link"></disable_collision>
  <disable_collision link1="L515_mounting_plate" link2="wrist_2_link"></disable_collision>
  <disable_collision link1="L515_mounting_plate" link2="wrist_3_link"></disable_collision>
  <disable_collision link1="L515_usb_plug_link" link2="left_bar_link"></disable_collision>
  <disable_collision link1="L515_usb_plug_link" link2="left_distal_phalanx_link"></disable_collision>
  <disable_collision link1="L515_usb_plug_link" link2="left_finger_tip_link"></disable_collision>
  <disable_collision link1="L515_usb_plug_link" link2="left_knuckle_link"></disable_collision>
  <disable_collision link1="L515_usb_plug_link" link2="left_proximal_phalanx_link"></disable_collision>
  <disable_collision link1="L515_usb_plug_link" link2="right_bar_link"></disable_collision>
  <disable_collision link1="L515_usb_plug_link" link2="right_distal_phalanx_link"></disable_collision>
  <disable_collision link1="L515_usb_plug_link" link2="right_finger_tip_link"></disable_collision>
  <disable_collision link1="L515_usb_plug_link" link2="right_knuckle_link"></disable_collision>
  <disable_collision link1="L515_usb_plug_link" link2="right_proximal_phalanx_link"></disable_collision>
  <disable_collision link1="L515_usb_plug_link" link2="robotiq_2f_base_palm"></disable_collision>
  <disable_collision link1="L515_usb_plug_link" link2="wrist_1_link"></disable_collision>
  <disable_collision link1="L515_usb_plug_link" link2="wrist_2_link"></disable_collision>
  <disable_collision link1="L515_usb_plug_link" link2="wrist_3_link"></disable_collision>
  <disable_collision link1="base_link_inertia" link2="shoulder_link"></disable_collision>
  <disable_collision link1="forearm_link" link2="upper_arm_link"></disable_collision>
  <disable_collision link1="forearm_link" link2="wrist_1_link"></disable_collision>
  <disable_collision link1="forearm_link" link2="wrist_2_link"></disable_collision>
  <disable_collision link1="left_bar_link" link2="left_distal_phalanx_link"></disable_collision>
  <disable_collision link1="left_bar_link" link2="left_finger_tip_link"></disable_collision>
  <disable_collision link1="left_bar_link" link2="left_knuckle_link"></disable_collision>
  <disable_collision link1="left_bar_link" link2="left_proximal_phalanx_link"></disable_collision>
  <disable_collision link1="left_bar_link" link2="right_bar_link"></disable_collision>
  <disable_collision link1="left_bar_link" link2="right_distal_phalanx_link"></disable_collision>
  <disable_collision link1="left_bar_link" link2="right_finger_tip_link"></disable_collision>
  <disable_collision link1="left_bar_link" link2="right_knuckle_link"></disable_collision>
  <disable_collision link1="left_bar_link" link2="right_proximal_phalanx_link"></disable_collision>
  <disable_collision link1="left_bar_link" link2="robotiq_2f_base_palm"></disable_collision>
  <disable_collision link1="left_bar_link" link2="wrist_1_link"></disable_collision>
  <disable_collision link1="left_bar_link" link2="wrist_2_link"></disable_collision>
  <disable_collision link1="left_bar_link" link2="wrist_3_link"></disable_collision>
  <disable_collision link1="left_distal_phalanx_link" link2="left_finger_tip_link"></disable_collision>
  <disable_collision link1="left_distal_phalanx_link" link2="left_knuckle_link"></disable_collision>
  <disable_collision link1="left_distal_phalanx_link" link2="left_proximal_phalanx_link"></disable_collision>
  <disable_collision link1="left_distal_phalanx_link" link2="right_bar_link"></disable_collision>
  <disable_collision link1="left_distal_phalanx_link" link2="right_distal_phalanx_link"></disable_collision>
  <disable_collision link1="left_distal_phalanx_link" link2="right_finger_tip_link"></disable_collision>
  <disable_collision link1="left_distal_phalanx_link" link2="right_knuckle_link"></disable_collision>
  <disable_collision link1="left_distal_phalanx_link" link2="right_proximal_phalanx_link"></disable_collision>
  <disable_collision link1="left_distal_phalanx_link" link2="robotiq_2f_base_palm"></disable_collision>
  <disable_collision link1="left_distal_phalanx_link" link2="wrist_1_link"></disable_collision>
  <disable_collision link1="left_distal_phalanx_link" link2="wrist_2_link"></disable_collision>
  <disable_collision link1="left_distal_phalanx_link" link2="wrist_3_link"></disable_collision>
  <disable_collision link1="left_finger_tip_link" link2="left_knuckle_link"></disable_collision>
  <disable_collision link1="left_finger_tip_link" link2="left_proximal_phalanx_link"></disable_collision>
  <disable_collision link1="left_finger_tip_link" link2="right_bar_link"></disable_collision>
  <disable_collision link1="left_finger_tip_link" link2="right_distal_phalanx_link"></disable_collision>
  <disable_collision link1="left_finger_tip_link" link2="right_finger_tip_link"></disable_collision>
  <disable_collision link1="left_finger_tip_link" link2="right_knuckle_link"></disable_collision>
  <disable_collision link1="left_finger_tip_link" link2="right_proximal_phalanx_link"></disable_collision>
  <disable_collision link1="left_finger_tip_link" link2="robotiq_2f_base_palm"></disable_collision>
  <disable_collision link1="left_finger_tip_link" link2="wrist_1_link"></disable_collision>
  <disable_collision link1="left_finger_tip_link" link2="wrist_2_link"></disable_collision>
  <disable_collision link1="left_finger_tip_link" link2="wrist_3_link"></disable_collision>
  <disable_collision link1="left_knuckle_link" link2="left_proximal_phalanx_link"></disable_collision>
  <disable_collision link1="left_knuckle_link" link2="right_bar_link"></disable_collision>
  <disable_collision link1="left_knuckle_link" link2="right_distal_phalanx_link"></disable_collision>
  <disable_collision link1="left_knuckle_link" link2="right_finger_tip_link"></disable_collision>
  <disable_collision link1="left_knuckle_link" link2="right_knuckle_link"></disable_collision>
  <disable_collision link1="left_knuckle_link" link2="right_proximal_phalanx_link"></disable_collision>
  <disable_collision link1="left_knuckle_link" link2="robotiq_2f_base_palm"></disable_collision>
  <disable_collision link1="left_knuckle_link" link2="wrist_1_link"></disable_collision>
  <disable_collision link1="left_knuckle_link" link2="wrist_2_link"></disable_collision>
  <disable_collision link1="left_knuckle_link" link2="wrist_3_link"></disable_collision>
  <disable_collision link1="left_proximal_phalanx_link" link2="right_bar_link"></disable_collision>
  <disable_collision link1="left_proximal_phalanx_link" link2="right_distal_phalanx_link"></disable_collision>
  <disable_collision link1="left_proximal_phalanx_link" link2="right_finger_tip_link"></disable_collision>
  <disable_collision link1="left_proximal_phalanx_link" link2="right_knuckle_link"></disable_collision>
  <disable_collision link1="left_proximal_phalanx_link" link2="right_proximal_phalanx_link"></disable_collision>
  <disable_collision link1="left_proximal_phalanx_link" link2="robotiq_2f_base_palm"></disable_collision>
  <disable_collision link1="left_proximal_phalanx_link" link2="wrist_1_link"></disable_collision>
  <disable_collision link1="left_proximal_phalanx_link" link2="wrist_2_link"></disable_collision>
  <disable_collision link1="left_proximal_phalanx_link" link2="wrist_3_link"></disable_collision>
  <disable_collision link1="right_bar_link" link2="right_distal_phalanx_link"></disable_collision>
  <disable_collision link1="right_bar_link" link2="right_finger_tip_link"></disable_collision>
  <disable_collision link1="right_bar_link" link2="right_knuckle_link"></disable_collision>
  <disable_collision link1="right_bar_link" link2="right_proximal_phalanx_link"></disable_collision>
  <disable_collision link1="right_bar_link" link2="robotiq_2f_base_palm"></disable_collision>
  <disable_collision link1="right_bar_link" link2="wrist_1_link"></disable_collision>
  <disable_collision link1="right_bar_link" link2="wrist_2_link"></disable_collision>
  <disable_collision link1="right_bar_link" link2="wrist_3_link"></disable_collision>
  <disable_collision link1="right_distal_phalanx_link" link2="right_finger_tip_link"></disable_collision>
  <disable_collision link1="right_distal_phalanx_link" link2="right_knuckle_link"></disable_collision>
  <disable_collision link1="right_distal_phalanx_link" link2="right_proximal_phalanx_link"></disable_collision>
  <disable_collision link1="right_distal_phalanx_link" link2="robotiq_2f_base_palm"></disable_collision>
  <disable_collision link1="right_distal_phalanx_link" link2="wrist_1_link"></disable_collision>
  <disable_collision link1="right_distal_phalanx_link" link2="wrist_2_link"></disable_collision>
  <disable_collision link1="right_distal_phalanx_link" link2="wrist_3_link"></disable_collision>
  <disable_collision link1="right_finger_tip_link" link2="right_knuckle_link"></disable_collision>
  <disable_collision link1="right_finger_tip_link" link2="right_proximal_phalanx_link"></disable_collision>
  <disable_collision link1="right_finger_tip_link" link2="robotiq_2f_base_palm"></disable_collision>
  <disable_collision link1="right_finger_tip_link" link2="wrist_1_link"></disable_collision>
  <disable_collision link1="right_finger_tip_link" link2="wrist_2_link"></disable_collision>
  <disable_collision link1="right_finger_tip_link" link2="wrist_3_link"></disable_collision>
  <disable_collision link1="right_knuckle_link" link2="right_proximal_phalanx_link"></disable_collision>
  <disable_collision link1="right_knuckle_link" link2="robotiq_2f_base_palm"></disable_collision>
  <disable_collision link1="right_knuckle_link" link2="wrist_1_link"></disable_collision>
  <disable_collision link1="right_knuckle_link" link2="wrist_2_link"></disable_collision>
  <disable_collision link1="right_knuckle_link" link2="wrist_3_link"></disable_collision>
  <disable_collision link1="right_proximal_phalanx_link" link2="robotiq_2f_base_palm"></disable_collision>
  <disable_collision link1="right_proximal_phalanx_link" link2="wrist_1_link"></disable_collision>
  <disable_collision link1="right_proximal_phalanx_link" link2="wrist_2_link"></disable_collision>
  <disable_collision link1="right_proximal_phalanx_link" link2="wrist_3_link"></disable_collision>
  <disable_collision link1="robotiq_2f_base_palm" link2="wrist_1_link"></disable_collision>
  <disable_collision link1="robotiq_2f_base_palm" link2="wrist_2_link"></disable_collision>
  <disable_collision link1="robotiq_2f_base_palm" link2="wrist_3_link"></disable_collision>
  <disable_collision link1="shoulder_link" link2="upper_arm_link"></disable_collision>
  <disable_collision link1="wrist_1_link" link2="wrist_2_link"></disable_collision>
  <disable_collision link1="wrist_1_link" link2="wrist_3_link"></disable_collision>
  <disable_collision link1="wrist_2_link" link2="wrist_3_link"></disable_collision>
</robot>